I'm sorry, but an uncaught exception occurred.

While running game code:
  File "game/Scripts/chapter4 - meeting flair.rpy", line 5, in script
    fi "CONTAINMENT BREACH IN SECTORS 6 - 13!"
Exception: Sayer 'fi' is not defined.

-- Full Traceback ------------------------------------------------------------

Full traceback:
  File "game/Scripts/chapter4 - meeting flair.rpy", line 5, in script
    fi "CONTAINMENT BREACH IN SECTORS 6 - 13!"
  File "C:\Users\rkski\Documents\renpy-8.1.0-sdk\renpy\ast.py", line 890, in execute
    who = eval_who(self.who, self.who_fast)
  File "C:\Users\rkski\Documents\renpy-8.1.0-sdk\renpy\ast.py", line 783, in eval_who
    raise Exception("Sayer '%s' is not defined." % who)
Exception: Sayer 'fi' is not defined.

Windows-10-10.0.19045 AMD64
Ren'Py 8.1.1.23052503+nightly
Erasers 1.0
Tue Jun 27 16:53:47 2023
